const x = 5

// x = 3

try {

    x = 2

} catch (e) {

    console.log(`Error: ${e}`)

}

console.log("final of the execution")